Workbook

Sheet 说明
A1: 六模型 × 三提示条件 × 每单元9张：162张结果填写模板
A3: 固定设计参数 | B3: 数值/规则 | D3: 模型代码 | E3: 模型名称 | F3: 每模型样本
A4: 模型数 | B4: 6 | D4: M1 | E4: ChatGPT Images 2.0 | F4: 27
A5: 提示条件数 | B5: 3 | D5: M2 | E5: gemini-3.1-flash-image | F5: 27
A6: 每“模型—提示词”单元 | B6: 9 | D6: M3 | E6: MAI-Image-2.5-Pro | F6: 27
A7: 总样本 | B7: 162 | D7: M4 | E7: Reve 2.1 | F7: 27
A8: 每模型 | B8: 27 | D8: M5 | E8: Seedream 5.0 Lite | F8: 27
A9: 每提示条件 | B9: 54 | D9: M6 | E9: HunyuanImage-3.0 | F9: 27
A10: 预测试 | B10: 18
A11: 留一模型分析 | B11: 6次；每次剔除27张、保留135张
A12: Bootstrap分层单元 | B12: 18
A13: 稳定判据 | B13: πj≥0.60 且六次留一模型至少5次入选
A16: 指标 | B16: 含义 | D16: 颜色说明 | E16: 用途
A17: f1 | B17: 屋顶、佛塔与比例 | D17: 黄色单元格 | E17: 需要人工录入/粘贴真实结果
A18: f2 | B18: 城墙与门楼 | D18: 绿色单元格 | E18: 由表内公式自动计算
A19: f3 | B19: 衣袍领型 | D19: 0/1/2/NA | E19: 原子指标编码；NA=对象未出现
A20: f4 | B20: 腰带配件 | D20: 总体Y | E20: 0=无明显失真；1=局部/可疑；2=明确/系统性失真
A21: f5 | B21: 头饰须发 | D21: 注意 | E21: 复杂统计（Bootstrap、Kappa、CART）建议由R/Python输出后粘贴到黄色单元格。
A22: f6 | B22: 书籍家具
A23: f7 | B23: 饮食贸易器皿
A24: f8 | B24: 兵器铠甲
A25: f9 | B25: 马匹马具车辆
A26: f10 | B26: 具体身份可辨识度
A27: f11 | B27: 族群标签化
A28: f12 | B28: 社会身份与互动
A29: f13 | B29: 位置遮挡
A30: f14 | B30: 景深透视方向
A31: f15 | B31: 线条笔触
A32: f16 | B32: 色彩材质
A33: f17 | B33: 形体文字结构幻觉
A34: f18 | B34: 提示词遵循度

Sheet 样本清单
A1: ImageID | B1: 模型代码 | C1: 模型名称 | D1: 提示条件 | E1: 提示名称 | F1: 重复序号 | G1: 建议文件名 | H1: 生成日期 | I1: 生成状态 | J1: 失败/拒绝原因 | K1: 备注
A2: M1_P1_01 | B2: M1 | C2: ChatGPT Images 2.0 | D2: P1 | E2: 低约束基线 | F2: 1 | G2: M1_P1_01.png
A3: M1_P1_02 | B3: M1 | C3: ChatGPT Images 2.0 | D3: P1 | E3: 低约束基线 | F3: 2 | G3: M1_P1_02.png
A4: M1_P1_03 | B4: M1 | C4: ChatGPT Images 2.0 | D4: P1 | E4: 低约束基线 | F4: 3 | G4: M1_P1_03.png
A5: M1_P1_04 | B5: M1 | C5: ChatGPT Images 2.0 | D5: P1 | E5: 低约束基线 | F5: 4 | G5: M1_P1_04.png
A6: M1_P1_05 | B6: M1 | C6: ChatGPT Images 2.0 | D6: P1 | E6: 低约束基线 | F6: 5 | G6: M1_P1_05.png
A7: M1_P1_06 | B7: M1 | C7: ChatGPT Images 2.0 | D7: P1 | E7: 低约束基线 | F7: 6 | G7: M1_P1_06.png
A8: M1_P1_07 | B8: M1 | C8: ChatGPT Images 2.0 | D8: P1 | E8: 低约束基线 | F8: 7 | G8: M1_P1_07.png
A9: M1_P1_08 | B9: M1 | C9: ChatGPT Images 2.0 | D9: P1 | E9: 低约束基线 | F9: 8 | G9: M1_P1_08.png
A10: M1_P1_09 | B10: M1 | C10: ChatGPT Images 2.0 | D10: P1 | E10: 低约束基线 | F10: 9 | G10: M1_P1_09.png
A11: M1_P2_01 | B11: M1 | C11: ChatGPT Images 2.0 | D11: P2 | E11: 考据约束 | F11: 1 | G11: M1_P2_01.png
A12: M1_P2_02 | B12: M1 | C12: ChatGPT Images 2.0 | D12: P2 | E12: 考据约束 | F12: 2 | G12: M1_P2_02.png
A13: M1_P2_03 | B13: M1 | C13: ChatGPT Images 2.0 | D13: P2 | E13: 考据约束 | F13: 3 | G13: M1_P2_03.png
... A163: M6_P3_09 | B163: M6 | C163: HunyuanImage-3.0 | D163: P3 | E163: 负向关系框架 | F163: 9 | G163: M6_P3_09.png

Sheet 编码员A
A1: ImageID | B1: 模型代码 | C1: 模型名称 | D1: 提示条件 | E1: 重复序号 | F1: 总体Y | G1: f1 | H1: f2 | I1: f3 | J1: f4 | K1: f5 | L1: f6 | M1: f7 | N1: f8 | O1: f9 | P1: f10 | Q1: f11 | R1: f12 | S1: f13 | T1: f14 | U1: f15 | V1: f16 | W1: f17 | X1: f18 | Y1: 编码备注
A2: ==样本清单!A2 -> M1_P1_01 | B2: ==样本清单!B2 -> M1 | C2: ==样本清单!C2 -> ChatGPT Images 2.0 | D2: ==样本清单!D2 -> P1 | E2: ==样本清单!F2 -> 1 | F2: 0 | G2: 0 | H2: 1 | I2: 0 | J2: 2 | K2: 0 | L2: 1 | M2: 1 | N2: NA | O2: 1 | P2: 0 | Q2: 0 | R2: 0 | S2: 2 | T2: 2 | U2: 0 | V2: 0 | W2: 1 | X2: 1
A3: ==样本清单!A3 -> M1_P1_02 | B3: ==样本清单!B3 -> M1 | C3: ==样本清单!C3 -> ChatGPT Images 2.0 | D3: ==样本清单!D3 -> P1 | E3: ==样本清单!F3 -> 2 | F3: 0 | G3: 1 | H3: 0 | I3: 0 | J3: 2 | K3: 0 | L3: 2 | M3: 2 | N3: NA | O3: 0 | P3: 0 | Q3: 0 | R3: 0 | S3: 1 | T3: 0 | U3: 1 | V3: 0 | W3: 0 | X3: 1
A4: ==样本清单!A4 -> M1_P1_03 | B4: ==样本清单!B4 -> M1 | C4: ==样本清单!C4 -> ChatGPT Images 2.0 | D4: ==样本清单!D4 -> P1 | E4: ==样本清单!F4 -> 3 | F4: 1 | G4: 1 | H4: 2 | I4: 0 | J4: 2 | K4: 0 | L4: 2 | M4: 2 | N4: NA | O4: 2 | P4: 0 | Q4: 1 | R4: 0 | S4: 1 | T4: 2 | U4: 0 | V4: 1 | W4: 1 | X4: 1
A5: ==样本清单!A5 -> M1_P1_04 | B5: ==样本清单!B5 -> M1 | C5: ==样本清单!C5 -> ChatGPT Images 2.0 | D5: ==样本清单!D5 -> P1 | E5: ==样本清单!F5 -> 4 | F5: 0 | G5: 0 | H5: 0 | I5: 0 | J5: 2 | K5: 0 | L5: 1 | M5: 1 | N5: NA | O5: 0 | P5: 0 | Q5: 0 | R5: 0 | S5: 2 | T5: 1 | U5: 1 | V5: 1 | W5: 1 | X5: 1
A6: ==样本清单!A6 -> M1_P1_05 | B6: ==样本清单!B6 -> M1 | C6: ==样本清单!C6 -> ChatGPT Images 2.0 | D6: ==样本清单!D6 -> P1 | E6: ==样本清单!F6 -> 5 | F6: 0 | G6: 0 | H6: 0 | I6: 0 | J6: 2 | K6: 0 | L6: 1 | M6: 1 | N6: 0 | O6: 2 | P6: 0 | Q6: 0 | R6: 0 | S6: 2 | T6: 1 | U6: 0 | V6: 1 | W6: 2 | X6: 1
A7: ==样本清单!A7 -> M1_P1_06 | B7: ==样本清单!B7 -> M1 | C7: ==样本清单!C7 -> ChatGPT Images 2.0 | D7: ==样本清单!D7 -> P1 | E7: ==样本清单!F7 -> 6 | F7: 0 | G7: 0 | H7: 0 | I7: 0 | J7: 1 | K7: 0 | L7: 0 | M7: 2 | N7: NA | O7: 1 | P7: 0 | Q7: 0 | R7: 0 | S7: 1 | T7: 0 | U7: 0 | V7: 1 | W7: 0 | X7: 0
A8: ==样本清单!A8 -> M1_P1_07 | B8: ==样本清单!B8 -> M1 | C8: ==样本清单!C8 -> ChatGPT Images 2.0 | D8: ==样本清单!D8 -> P1 | E8: ==样本清单!F8 -> 7 | F8: 1 | G8: 2 | H8: 1 | I8: 1 | J8: 1 | K8: 0 | L8: 2 | M8: 1 | N8: NA | O8: 0 | P8: 0 | Q8: 0 | R8: 0 | S8: 0 | T8: 1 | U8: 1 | V8: 1 | W8: 2 | X8: 1
A9: ==样本清单!A9 -> M1_P1_08 | B9: ==样本清单!B9 -> M1 | C9: ==样本清单!C9 -> ChatGPT Images 2.0 | D9: ==样本清单!D9 -> P1 | E9: ==样本清单!F9 -> 8 | F9: 1 | G9: 0 | H9: 1 | I9: 0 | J9: 2 | K9: 0 | L9: 2 | M9: 2 | N9: 2 | O9: 2 | P9: 0 | Q9: 0 | R9: 0 | S9: 2 | T9: 1 | U9: 1 | V9: 1 | W9: 2 | X9: 1
A10: ==样本清单!A10 -> M1_P1_09 | B10: ==样本清单!B10 -> M1 | C10: ==样本清单!C10 -> ChatGPT Images 2.0 | D10: ==样本清单!D10 -> P1 | E10: ==样本清单!F10 -> 9 | F10: 0 | G10: 2 | H10: 2 | I10: 0 | J10: 2 | K10: 0 | L10: 1 | M10: 0 | N10: 0 | O10: 2 | P10: 0 | Q10: 0 | R10: 0 | S10: 2 | T10: 1 | U10: 1 | V10: 2 | W10: 1 | X10: 1
A11: ==样本清单!A11 -> M1_P2_01 | B11: ==样本清单!B11 -> M1 | C11: ==样本清单!C11 -> ChatGPT Images 2.0 | D11: ==样本清单!D11 -> P2 | E11: ==样本清单!F11 -> 1 | F11: 1 | G11: 0 | H11: 0 | I11: 0 | J11: 2 | K11: 0 | L11: 2 | M11: 2 | N11: NA | O11: 2 | P11: 0 | Q11: 0 | R11: 0 | S11: 2 | T11: 1 | U11: 2 | V11: 1 | W11: 2 | X11: 1
A12: ==样本清单!A12 -> M1_P2_02 | B12: ==样本清单!B12 -> M1 | C12: ==样本清单!C12 -> ChatGPT Images 2.0 | D12: ==样本清单!D12 -> P2 | E12: ==样本清单!F12 -> 2 | F12: 1 | G12: 0 | H12: 1 | I12: 0 | J12: 0 | K12: 1 | L12: 2 | M12: 1 | N12: NA | O12: 2 | P12: 0 | Q12: 0 | R12: 0 | S12: 2 | T12: 1 | U12: 2 | V12: 2 | W12: 2 | X12: 2
A13: ==样本清单!A13 -> M1_P2_03 | B13: ==样本清单!B13 -> M1 | C13: ==样本清单!C13 -> ChatGPT Images 2.0 | D13: ==样本清单!D13 -> P2 | E13: ==样本清单!F13 -> 3 | F13: 1 | G13: 0 | H13: 1 | I13: 1 | J13: 1 | K13: 0 | L13: 2 | M13: 2 | N13: NA | O13: 2 | P13: 0 | Q13: 0 | R13: 0 | S13: 2 | T13: 1 | U13: 2 | V13: 1 | W13: 2 | X13: 1
A14: ==样本清单!A14 -> M1_P2_04 | B14: ==样本清单!B14 -> M1 | C14: ==样本清单!C14 -> ChatGPT Images 2.0 | D14: ==样本清单!D14 -> P2 | E14: ==样本清单!F14 -> 4 | F14: 1 | G14: 2 | H14: 1 | I14: 1 | J14: 2 | K14: 2 | L14: 2 | M14: 2 | N14: 2 | O14: 2 | P14: 0 | Q14: 0 | R14: 0 | S14: 2 | T14: 1 | U14: 1 | V14: 1 | W14: 2 | X14: 1
A15: ==样本清单!A15 -> M1_P2_05 | B15: ==样本清单!B15 -> M1 | C15: ==样本清单!C15 -> ChatGPT Images 2.0 | D15: ==样本清单!D15 -> P2 | E15: ==样本清单!F15 -> 5 | F15: 2 | G15: 1 | H15: 2 | I15: 0 | J15: 1 | K15: 1 | L15: 2 | M15: 2 | N15: NA | O15: 2 | P15: 0 | Q15: 0 | R15: 0 | S15: 2 | T15: 1 | U15: 1 | V15: 1 | W15: 2 | X15: 2
A16: ==样本清单!A16 -> M1_P2_06 | B16: ==样本清单!B16 -> M1 | C16: ==样本清单!C16 -> ChatGPT Images 2.0 | D16: ==样本清单!D16 -> P2 | E16: ==样本清单!F16 -> 6 | F16: 1 | G16: 0 | H16: 0 | I16: 0 | J16: 2 | K16: 0 | L16: 1 | M16: 2 | N16: 2 | O16: 2 | P16: 0 | Q16: 0 | R16: 0 | S16: 1 | T16: 1 | U16: 1 | V16: 1 | W16: 2 | X16: 1
A17: ==样本清单!A17 -> M1_P2_07 | B17: ==样本清单!B17 -> M1 | C17: ==样本清单!C17 -> ChatGPT Images 2.0 | D17: ==样本清单!D17 -> P2 | E17: ==样本清单!F17 -> 7 | F17: 1 | G17: 0 | H17: 0 | I17: 0 | J17: 2 | K17: 2 | L17: 2 | M17: 2 | N17: 2 | O17: 2 | P17: 0 | Q17: 0 | R17: 0 | S17: 2 | T17: 1 | U17: 2 | V17: 1 | W17: 2 | X17: 1
A18: ==样本清单!A18 -> M1_P2_08 | B18: ==样本清单!B18 -> M1 | C18: ==样本清单!C18 -> ChatGPT Images 2.0 | D18: ==样本清单!D18 -> P2 | E18: ==样本清单!F18 -> 8 | F18: 2 | G18: 0 | H18: 2 | I18: 0 | J18: 0 | K18: 1 | L18: 1 | M18: 2 | N18: NA | O18: 2 | P18: 0 | Q18: 0 | R18: 0 | S18: 2 | T18: 2 | U18: 1 | V18: 1 | W18: 2 | X18: 2
A19: ==样本清单!A19 -> M1_P2_09 | B19: ==样本清单!B19 -> M1 | C19: ==样本清单!C19 -> ChatGPT Images 2.0 | D19: ==样本清单!D19 -> P2 | E19: ==样本清单!F19 -> 9 | F19: 1 | G19: 1 | H19: 1 | I19: 1 | J19: 2 | K19: 0 | L19: 2 | M19: 2 | N19: NA | O19: 2 | P19: 0 | Q19: 0 | R19: 0 | S19: 2 | T19: 2 | U19: 1 | V19: 1 | W19: 2 | X19: 2
A20: ==样本清单!A20 -> M1_P3_01 | B20: ==样本清单!B20 -> M1 | C20: ==样本清单!C20 -> ChatGPT Images 2.0 | D20: ==样本清单!D20 -> P3 | E20: ==样本清单!F20 -> 1 | F20: 0 | G20: 1 | H20: 1 | I20: 1 | J20: 1 | K20: 1 | L20: 2 | M20: 2 | N20: 1 | O20: 2 | P20: 0 | Q20: 0 | R20: 0 | S20: 2 | T20: 1 | U20: 2 | V20: 1 | W20: 2 | X20: 1
A21: ==样本清单!A21 -> M1_P3_02 | B21: ==样本清单!B21 -> M1 | C21: ==样本清单!C21 -> ChatGPT Images 2.0 | D21: ==样本清单!D21 -> P3 | E21: ==样本清单!F21 -> 2 | F21: 1 | G21: 1 | H21: 2 | I21: 1 | J21: 2 | K21: 2 | L21: 2 | M21: 2 | N21: 1 | O21: 2 | P21: 0 | Q21: 0 | R21: 0 | S21: 2 | T21: 1 | U21: 1 | V21: 1 | W21: 2 | X21: 1
A22: ==样本清单!A22 -> M1_P3_03 | B22: ==样本清单!B22 -> M1 | C22: ==样本清单!C22 -> ChatGPT Images 2.0 | D22: ==样本清单!D22 -> P3 | E22: ==样本清单!F22 -> 3 | F22: 1 | G22: 2 | H22: 2 | I22: 1 | J22: 2 | K22: 0 | L22: 2 | M22: 2 | N22: 1 | O22: 2 | P22: 0 | Q22: 0 | R22: 0 | S22: 2 | T22: 1 | U22: 2 | V22: 1 | W22: 2 | X22: 1
A23: ==样本清单!A23 -> M1_P3_04 | B23: ==样本清单!B23 -> M1 | C23: ==样本清单!C23 -> ChatGPT Images 2.0 | D23: ==样本清单!D23 -> P3 | E23: ==样本清单!F23 -> 4 | F23: 2 | G23: 2 | H23: 2 | I23: 1 | J23: 2 | K23: 1 | L23: 2 | M23: 2 | N23: 1 | O23: 2 | P23: 0 | Q23: 0 | R23: 0 | S23: 2 | T23: 2 | U23: 1 | V23: 1 | W23: 2 | X23: 1
A24: ==样本清单!A24 -> M1_P3_05 | B24: ==样本清单!B24 -> M1 | C24: ==样本清单!C24 -> ChatGPT Images 2.0 | D24: ==样本清单!D24 -> P3 | E24: ==样本清单!F24 -> 5 | F24: 1 | G24: 1 | H24: 2 | I24: 2 | J24: 2 | K24: 2 | L24: 2 | M24: 2 | N24: 0 | O24: 1 | P24: 0 | Q24: 0 | R24: 1 | S24: 2 | T24: 2 | U24: 2 | V24: 1 | W24: 2 | X24: 1
A25: ==样本清单!A25 -> M1_P3_06 | B25: ==样本清单!B25 -> M1 | C25: ==样本清单!C25 -> ChatGPT Images 2.0 | D25: ==样本清单!D25 -> P3 | E25: ==样本清单!F25 -> 6 | F25: 2 | G25: 2 | H25: 2 | I25: 1 | J25: 1 | K25: 1 | L25: 2 | M25: 2 | N25: 1 | O25: 2 | P25: 0 | Q25: 0 | R25: 0 | S25: 2 | T25: 2 | U25: 1 | V25: 2 | W25: 2 | X25: 2
A26: ==样本清单!A26 -> M1_P3_07 | B26: ==样本清单!B26 -> M1 | C26: ==样本清单!C26 -> ChatGPT Images 2.0 | D26: ==样本清单!D26 -> P3 | E26: ==样本清单!F26 -> 7 | F26: 1 | G26: 2 | H26: 2 | I26: 1 | J26: 1 | K26: 0 | L26: 1 | M26: 2 | N26: 0 | O26: 2 | P26: 0 | Q26: 0 | R26: 0 | S26: 1 | T26: 1 | U26: 2 | V26: 1 | W26: 2 | X26: 1
A27: ==样本清单!A27 -> M1_P3_08 | B27: ==样本清单!B27 -> M1 | C27: ==样本清单!C27 -> ChatGPT Images 2.0 | D27: ==样本清单!D27 -> P3 | E27: ==样本清单!F27 -> 8 | F27: 1 | G27: 1 | H27: 2 | I27: 1 | J27: 2 | K27: 2 | L27: 2 | M27: 2 | N27: 2 | O27: 2 | P27: 0 | Q27: 0 | R27: 0 | S27: 2 | T27: 1 | U27: 2 | V27: 1 | W27: 2 | X27: 2
A28: ==样本清单!A28 -> M1_P3_09 | B28: ==样本清单!B28 -> M1 | C28: ==样本清单!C28 -> ChatGPT Images 2.0 | D28: ==样本清单!D28 -> P3 | E28: ==样本清单!F28 -> 9 | F28: 2 | G28: 2 | H28: 2 | I28: 1 | J28: 2 | K28: 0 | L28: 2 | M28: 2 | N28: 0 | O28: 2 | P28: 0 | Q28: 0 | R28: 0 | S28: 2 | T28: 1 | U28: 1 | V28: 1 | W28: 2 | X28: 2
A29: ==样本清单!A29 -> M2_P1_01 | B29: ==样本清单!B29 -> M2 | C29: ==样本清单!C29 -> gemini-3.1-flash-image | D29: ==样本清单!D29 -> P1 | E29: ==样本清单!F29 -> 1 | F29: 1 | G29: 0 | H29: 1 | I29: 0 | J29: 1 | K29: 0 | L29: 1 | M29: 0 | N29: 0 | O29: 0 | P29: 0 | Q29: 0 | R29: 0 | S29: 0 | T29: 0 | U29: 0 | V29: 1 | W29: 0 | X29: 0
A30: ==样本清单!A30 -> M2_P1_02 | B30: ==样本清单!B30 -> M2 | C30: ==样本清单!C30 -> gemini-3.1-flash-image | D30: ==样本清单!D30 -> P1 | E30: ==样本清单!F30 -> 2 | F30: 1 | G30: 0 | H30: 2 | I30: 1 | J30: 0 | K30: 0 | L30: 0 | M30: 1 | N30: 0 | O30: 0 | P30: 0 | Q30: 0 | R30: 0 | S30: 0 | T30: 1 | U30: 0 | V30: 2 | W30: 1 | X30: 1
A31: ==样本清单!A31 -> M2_P1_03 | B31: ==样本清单!B31 -> M2 | C31: ==样本清单!C31 -> gemini-3.1-flash-image | D31: ==样本清单!D31 -> P1 | E31: ==样本清单!F31 -> 3 | F31: 2 | G31: 0 | H31: 1 | I31: 0 | J31: 1 | K31: 1 | L31: 2 | M31: 1 | N31: NA | O31: 1 | P31: 0 | Q31: 0 | R31: 0 | S31: 1 | T31: 0 | U31: 0 | V31: 1 | W31: 1 | X31: 1
A32: ==样本清单!A32 -> M2_P1_04 | B32: ==样本清单!B32 -> M2 | C32: ==样本清单!C32 -> gemini-3.1-flash-image | D32: ==样本清单!D32 -> P1 | E32: ==样本清单!F32 -> 4 | F32: 2 | G32: 2 | H32: 2 | I32: 0 | J32: 0 | K32: 0 | L32: 2 | M32: 0 | N32: 1 | O32: 0 | P32: 0 | Q32: 0 | R32: 0 | S32: 1 | T32: 0 | U32: 1 | V32: 1 | W32: 2 | X32: 2
A33: ==样本清单!A33 -> M2_P1_05 | B33: ==样本清单!B33 -> M2 | C33: ==样本清单!C33 -> gemini-3.1-flash-image | D33: ==样本清单!D33 -> P1 | E33: ==样本清单!F33 -> 5 | F33: 1 | G33: 1 | H33: 2 | I33: 0 | J33: 2 | K33: 0 | L33: 1 | M33: 2 | N33: 1 | O33: 1 | P33: 0 | Q33: 0 | R33: 0 | S33: 0 | T33: 0 | U33: 0 | V33: 1 | W33: 1 | X33: 2
A34: ==样本清单!A34 -> M2_P1_06 | B34: ==样本清单!B34 -> M2 | C34: ==样本清单!C34 -> gemini-3.1-flash-image | D34: ==样本清单!D34 -> P1 | E34: ==样本清单!F34 -> 6 | F34: 1 | G34: 0 | H34: 2 | I34: 0 | J34: 2 | K34: 0 | L34: 0 | M34: 0 | N34: NA | O34: 1 | P34: 0 | Q34: 0 | R34: 0 | S34: 0 | T34: 0 | U34: 1 | V34: 1 | W34: 2 | X34: 1
A35: ==样本清单!A35 -> M2_P1_07 | B35: ==样本清单!B35 -> M2 | C35: ==样本清单!C35 -> gemini-3.1-flash-image | D35: ==样本清单!D35 -> P1 | E35: ==样本清单!F35 -> 7 | F35: 2 | G35: 2 | H35: 1 | I35: 1 | J35: 2 | K35: 0 | L35: 0 | M35: 0 | N35: NA | O35: 0 | P35: 0 | Q35: 0 | R35: 0 | S35: 0 | T35: 1 | U35: 1 | V35: 1 | W35: 2 | X35: 1
A36: ==样本清单!A36 -> M2_P1_08 | B36: ==样本清单!B36 -> M2 | C36: ==样本清单!C36 -> gemini-3.1-flash-image | D36: ==样本清单!D36 -> P1 | E36: ==样本清单!F36 -> 8 | F36: 2 | G36: 0 | H36: 1 | I36: 1 | J36: 2 | K36: 0 | L36: 1 | M36: 1 | N36: 1 | O36: 1 | P36: 0 | Q36: 0 | R36: 0 | S36: 0 | T36: 1 | U36: 0 | V36: 1 | W36: 1 | X36: 1
A37: ==样本清单!A37 -> M2_P1_09 | B37: ==样本清单!B37 -> M2 | C37: ==样本清单!C37 -> gemini-3.1-flash-image | D37: ==样本清单!D37 -> P1 | E37: ==样本清单!F37 -> 9 | F37: 1 | G37: 2 | H37: 2 | I37: 1 | J37: 2 | K37: 0 | L37: 2 | M37: 1 | N37: NA | O37: 0 | P37: 0 | Q37: 0 | R37: 0 | S37: 1 | T37: 0 | U37: 0 | V37: 1 | W37: 2 | X37: 2
A38: ==样本清单!A38 -> M2_P2_01 | B38: ==样本清单!B38 -> M2 | C38: ==样本清单!C38 -> gemini-3.1-flash-image | D38: ==样本清单!D38 -> P2 | E38: ==样本清单!F38 -> 1 | F38: 1 | G38: 0 | H38: 2 | I38: 1 | J38: 2 | K38: 0 | L38: 1 | M38: 2 | N38: NA | O38: 2 | P38: 0 | Q38: 0 | R38: 0 | S38: 2 | T38: 1 | U38: 1 | V38: 1 | W38: 1 | X38: 2
A39: ==样本清单!A39 -> M2_P2_02 | B39: ==样本清单!B39 -> M2 | C39: ==样本清单!C39 -> gemini-3.1-flash-image | D39: ==样本清单!D39 -> P2 | E39: ==样本清单!F39 -> 2 | F39: 2 | G39: 1 | H39: 2 | I39: 1 | J39: 0 | K39: 1 | L39: 1 | M39: 2 | N39: 1 | O39: 1 | P39: 0 | Q39: 1 | R39: 0 | S39: 2 | T39: 2 | U39: 1 | V39: 1 | W39: 2 | X39: 1
A40: ==样本清单!A40 -> M2_P2_03 | B40: ==样本清单!B40 -> M2 | C40: ==样本清单!C40 -> gemini-3.1-flash-image | D40: ==样本清单!D40 -> P2 | E40: ==样本清单!F40 -> 3 | F40: 1 | G40: 1 | H40: 1 | I40: 1 | J40: 0 | K40: 0 | L40: 2 | M40: 2 | N40: 0 | O40: 1 | P40: 0 | Q40: 0 | R40: 0 | S40: 2 | T40: 1 | U40: 1 | V40: 1 | W40: 2 | X40: 1
...

Sheet 编码员B
A1: ImageID | B1: 模型代码 | C1: 模型名称 | D1: 提示条件 | E1: 重复序号 | F1: 总体Y | G1: f1 | H1: f2 | I1: f3 | J1: f4 | K1: f5 | L1: f6 | M1: f7 | N1: f8 | O1: f9 | P1: f10 | Q1: f11 | R1: f12 | S1: f13 | T1: f14 | U1: f15 | V1: f16 | W1: f17 | X1: f18 | Y1: 编码备注
A2: ==样本清单!A2 -> M1_P1_01 | B2: ==样本清单!B2 -> M1 | C2: ==样本清单!C2 -> ChatGPT Images 2.0 | D2: ==样本清单!D2 -> P1 | E2: ==样本清单!F2 -> 1 | F2: 1 | G2: 1 | H2: 1 | I2: 0 | J2: 2 | K2: 0 | L2: 0 | M2: 2 | N2: NA | O2: 0 | P2: 0 | Q2: 0 | R2: 0 | S2: 1 | T2: 1 | U2: 1 | V2: 1 | W2: 2 | X2: 0
A3: ==样本清单!A3 -> M1_P1_02 | B3: ==样本清单!B3 -> M1 | C3: ==样本清单!C3 -> ChatGPT Images 2.0 | D3: ==样本清单!D3 -> P1 | E3: ==样本清单!F3 -> 2 | F3: 0 | G3: 1 | H3: 1 | I3: 0 | J3: 1 | K3: 0 | L3: 1 | M3: 2 | N3: NA | O3: 0 | P3: 0 | Q3: 0 | R3: 0 | S3: 1 | T3: 1 | U3: 2 | V3: 1 | W3: 2 | X3: 1
A4: ==样本清单!A4 -> M1_P1_03 | B4: ==样本清单!B4 -> M1 | C4: ==样本清单!C4 -> ChatGPT Images 2.0 | D4: ==样本清单!D4 -> P1 | E4: ==样本清单!F4 -> 3 | F4: 0 | G4: 0 | H4: 1 | I4: 0 | J4: 2 | K4: 0 | L4: 1 | M4: 2 | N4: NA | O4: 1 | P4: 0 | Q4: 0 | R4: 0 | S4: 1 | T4: 1 | U4: 0 | V4: 1 | W4: 1 | X4: 0
A5: ==样本清单!A5 -> M1_P1_04 | B5: ==样本清单!B5 -> M1 | C5: ==样本清单!C5 -> ChatGPT Images 2.0 | D5: ==样本清单!D5 -> P1 | E5: ==样本清单!F5 -> 4 | F5: 0 | G5: 1 | H5: 1 | I5: 0 | J5: 2 | K5: 0 | L5: 2 | M5: 2 | N5: NA | O5: 1 | P5: 0 | Q5: 0 | R5: 0 | S5: 1 | T5: 1 | U5: 1 | V5: 1 | W5: 1 | X5: 0
A6: ==样本清单!A6 -> M1_P1_05 | B6: ==样本清单!B6 -> M1 | C6: ==样本清单!C6 -> ChatGPT Images 2.0 | D6: ==样本清单!D6 -> P1 | E6: ==样本清单!F6 -> 5 | F6: 1 | G6: 1 | H6: 1 | I6: 0 | J6: 2 | K6: 0 | L6: 0 | M6: 2 | N6: 0 | O6: 2 | P6: 0 | Q6: 0 | R6: 0 | S6: 2 | T6: 2 | U6: 1 | V6: 1 | W6: 1 | X6: 1
A7: ==样本清单!A7 -> M1_P1_06 | B7: ==样本清单!B7 -> M1 | C7: ==样本清单!C7 -> ChatGPT Images 2.0 | D7: ==样本清单!D7 -> P1 | E7: ==样本清单!F7 -> 6 | F7: 1 | G7: 1 | H7: 1 | I7: 0 | J7: 1 | K7: 0 | L7: 0 | M7: 2 | N7: NA | O7: 0 | P7: 0 | Q7: 0 | R7: 0 | S7: 1 | T7: 1 | U7: 1 | V7: 1 | W7: 1 | X7: 0
A8: ==样本清单!A8 -> M1_P1_07 | B8: ==样本清单!B8 -> M1 | C8: ==样本清单!C8 -> ChatGPT Images 2.0 | D8: ==样本清单!D8 -> P1 | E8: ==样本清单!F8 -> 7 | F8: 2 | G8: 2 | H8: 1 | I8: 1 | J8: 1 | K8: 0 | L8: 1 | M8: 2 | N8: 0 | O8: 0 | P8: 0 | Q8: 0 | R8: 0 | S8: 2 | T8: 1 | U8: 1 | V8: 1 | W8: 2 | X8: 2
A9: ==样本清单!A9 -> M1_P1_08 | B9: ==样本清单!B9 -> M1 | C9: ==样本清单!C9 -> ChatGPT Images 2.0 | D9: ==样本清单!D9 -> P1 | E9: ==样本清单!F9 -> 8 | F9: 1 | G9: 1 | H9: 1 | I9: 0 | J9: 2 | K9: 0 | L9: 2 | M9: 2 | N9: 2 | O9: 2 | P9: 0 | Q9: 0 | R9: 0 | S9: 2 | T9: 2 | U9: 1 | V9: 1 | W9: 2 | X9: 1
A10: ==样本清单!A10 -> M1_P1_09 | B10: ==样本清单!B10 -> M1 | C10: ==样本清单!C10 -> ChatGPT Images 2.0 | D10: ==样本清单!D10 -> P1 | E10: ==样本清单!F10 -> 9 | F10: 1 | G10: 1 | H10: 1 | I10: 0 | J10: 1 | K10: 0 | L10: 0 | M10: 2 | N10: 1 | O10: 1 | P10: 0 | Q10: 0 | R10: 0 | S10: 2 | T10: 1 | U10: 1 | V10: 1 | W10: 2 | X10: 1
A11: ==样本清单!A11 -> M1_P2_01 | B11: ==样本清单!B11 -> M1 | C11: ==样本清单!C11 -> ChatGPT Images 2.0 | D11: ==样本清单!D11 -> P2 | E11: ==样本清单!F11 -> 1 | F11: 1 | G11: 0 | H11: 0 | I11: 0 | J11: 1 | K11: 0 | L11: 2 | M11: 2 | N11: NA | O11: 2 | P11: 0 | Q11: 0 | R11: 0 | S11: 2 | T11: 2 | U11: 2 | V11: 1 | W11: 2 | X11: 1
A12: ==样本清单!A12 -> M1_P2_02 | B12: ==样本清单!B12 -> M1 | C12: ==样本清单!C12 -> ChatGPT Images 2.0 | D12: ==样本清单!D12 -> P2 | E12: ==样本清单!F12 -> 2 | F12: 1 | G12: 0 | H12: 0 | I12: 1 | J12: 0 | K12: 2 | L12: 2 | M12: 2 | N12: NA | O12: 2 | P12: 0 | Q12: 0 | R12: 0 | S12: 2 | T12: 2 | U12: 2 | V12: 2 | W12: 2 | X12: 2
A13: ==样本清单!A13 -> M1_P2_03 | B13: ==样本清单!B13 -> M1 | C13: ==样本清单!C13 -> ChatGPT Images 2.0 | D13: ==样本清单!D13 -> P2 | E13: ==样本清单!F13 -> 3 | F13: 1 | G13: 0 | H13: 0 | I13: 1 | J13: 0 | K13: 0 | L13: 2 | M13: 2 | N13: NA | O13: 2 | P13: 0 | Q13: 0 | R13: 0 | S13: 2 | T13: 1 | U13: 2 | V13: 1 | W13: 2 | X13: 2
A14: ==样本清单!A14 -> M1_P2_04 | B14: ==样本清单!B14 -> M1 | C14: ==样本清单!C14 -> ChatGPT Images 2.0 | D14: ==样本清单!D14 -> P2 | E14: ==样本清单!F14 -> 4 | F14: 1 | G14: 2 | H14: 1 | I14: 1 | J14: 1 | K14: 2 | L14: 2 | M14: 2 | N14: 2 | O14: 2 | P14: 0 | Q14: 0 | R14: 0 | S14: 2 | T14: 1 | U14: 2 | V14: 2 | W14: 2 | X14: 1
A15: ==样本清单!A15 -> M1_P2_05 | B15: ==样本清单!B15 -> M1 | C15: ==样本清单!C15 -> ChatGPT Images 2.0 | D15: ==样本清单!D15 -> P2 | E15: ==样本清单!F15 -> 5 | F15: 1 | G15: 2 | H15: 2 | I15: 0 | J15: 1 | K15: 2 | L15: 2 | M15: 2 | N15: NA | O15: 2 | P15: 0 | Q15: 0 | R15: 0 | S15: 2 | T15: 1 | U15: 2 | V15: 1 | W15: 2 | X15: 1
A16: ==样本清单!A16 -> M1_P2_06 | B16: ==样本清单!B16 -> M1 | C16: ==样本清单!C16 -> ChatGPT Images 2.0 | D16: ==样本清单!D16 -> P2 | E16: ==样本清单!F16 -> 6 | F16: 1 | G16: 0 | H16: 0 | I16: 0 | J16: 2 | K16: 0 | L16: 2 | M16: 2 | N16: NA | O16: 2 | P16: 0 | Q16: 0 | R16: 0 | S16: 2 | T16: 1 | U16: 2 | V16: 1 | W16: 2 | X16: 1
A17: ==样本清单!A17 -> M1_P2_07 | B17: ==样本清单!B17 -> M1 | C17: ==样本清单!C17 -> ChatGPT Images 2.0 | D17: ==样本清单!D17 -> P2 | E17: ==样本清单!F17 -> 7 | F17: 1 | G17: 0 | H17: 0 | I17: 0 | J17: 2 | K17: 2 | L17: 2 | M17: 2 | N17: 2 | O17: 2 | P17: 0 | Q17: 0 | R17: 0 | S17: 2 | T17: 1 | U17: 2 | V17: 1 | W17: 2 | X17: 1
A18: ==样本清单!A18 -> M1_P2_08 | B18: ==样本清单!B18 -> M1 | C18: ==样本清单!C18 -> ChatGPT Images 2.0 | D18: ==样本清单!D18 -> P2 | E18: ==样本清单!F18 -> 8 | F18: 1 | G18: 1 | H18: 2 | I18: 0 | J18: 0 | K18: 2 | L18: 2 | M18: 2 | N18: NA | O18: 2 | P18: 0 | Q18: 0 | R18: 0 | S18: 2 | T18: 1 | U18: 1 | V18: 1 | W18: 2 | X18: 1
A19: ==样本清单!A19 -> M1_P2_09 | B19: ==样本清单!B19 -> M1 | C19: ==样本清单!C19 -> ChatGPT Images 2.0 | D19: ==样本清单!D19 -> P2 | E19: ==样本清单!F19 -> 9 | F19: 1 | G19: 0 | H19: 0 | I19: 1 | J19: 1 | K19: 0 | L19: 2 | M19: 2 | N19: NA | O19: 2 | P19: 0 | Q19: 0 | R19: 0 | S19: 2 | T19: 1 | U19: 2 | V19: 1 | W19: 2 | X19: 1
A20: ==样本清单!A20 -> M1_P3_01 | B20: ==样本清单!B20 -> M1 | C20: ==样本清单!C20 -> ChatGPT Images 2.0 | D20: ==样本清单!D20 -> P3 | E20: ==样本清单!F20 -> 1 | F20: 1 | G20: 1 | H20: 1 | I20: 1 | J20: 1 | K20: 2 | L20: 2 | M20: 2 | N20: 1 | O20: 2 | P20: 0 | Q20: 0 | R20: 0 | S20: 2 | T20: 1 | U20: 2 | V20: 1 | W20: 2 | X20: 1
A21: ==样本清单!A21 -> M1_P3_02 | B21: ==样本清单!B21 -> M1 | C21: ==样本清单!C21 -> ChatGPT Images 2.0 | D21: ==样本清单!D21 -> P3 | E21: ==样本清单!F21 -> 2 | F21: 1 | G21: 1 | H21: 1 | I21: 1 | J21: 1 | K21: 1 | L21: 2 | M21: 2 | N21: 1 | O21: 2 | P21: 0 | Q21: 0 | R21: 0 | S21: 2 | T21: 2 | U21: 2 | V21: 2 | W21: 2 | X21: 2
A22: ==样本清单!A22 -> M1_P3_03 | B22: ==样本清单!B22 -> M1 | C22: ==样本清单!C22 -> ChatGPT Images 2.0 | D22: ==样本清单!D22 -> P3 | E22: ==样本清单!F22 -> 3 | F22: 1 | G22: 1 | H22: 2 | I22: 1 | J22: 2 | K22: 0 | L22: 2 | M22: 2 | N22: 0 | O22: 2 | P22: 0 | Q22: 0 | R22: 0 | S22: 2 | T22: 2 | U22: 2 | V22: 2 | W22: 2 | X22: 2
A23: ==样本清单!A23 -> M1_P3_04 | B23: ==样本清单!B23 -> M1 | C23: ==样本清单!C23 -> ChatGPT Images 2.0 | D23: ==样本清单!D23 -> P3 | E23: ==样本清单!F23 -> 4 | F23: 2 | G23: 1 | H23: 2 | I23: 1 | J23: 2 | K23: 0 | L23: 2 | M23: 2 | N23: 1 | O23: 2 | P23: 0 | Q23: 0 | R23: 0 | S23: 2 | T23: 2 | U23: 2 | V23: 2 | W23: 2 | X23: 2
A24: ==样本清单!A24 -> M1_P3_05 | B24: ==样本清单!B24 -> M1 | C24: ==样本清单!C24 -> ChatGPT Images 2.0 | D24: ==样本清单!D24 -> P3 | E24: ==样本清单!F24 -> 5 | F24: 2 | G24: 2 | H24: 2 | I24: 2 | J24: 2 | K24: 2 | L24: 2 | M24: 2 | N24: 1 | O24: 1 | P24: 0 | Q24: 0 | R24: 1 | S24: 2 | T24: 2 | U24: 2 | V24: 2 | W24: 2 | X24: 2
A25: ==样本清单!A25 -> M1_P3_06 | B25: ==样本清单!B25 -> M1 | C25: ==样本清单!C25 -> ChatGPT Images 2.0 | D25: ==样本清单!D25 -> P3 | E25: ==样本清单!F25 -> 6 | F25: 2 | G25: 2 | H25: 2 | I25: 2 | J25: 2 | K25: 2 | L25: 2 | M25: 2 | N25: 2 | O25: 2 | P25: 1 | Q25: 0 | R25: 1 | S25: 2 | T25: 2 | U25: 2 | V25: 2 | W25: 2 | X25: 2
A26: ==样本清单!A26 -> M1_P3_07 | B26: ==样本清单!B26 -> M1 | C26: ==样本清单!C26 -> ChatGPT Images 2.0 | D26: ==样本清单!D26 -> P3 | E26: ==样本清单!F26 -> 7 | F26: 2 | G26: 2 | H26: 1 | I26: 1 | J26: 1 | K26: 0 | L26: 2 | M26: 2 | N26: 0 | O26: 2 | P26: 0 | Q26: 0 | R26: 0 | S26: 2 | T26: 2 | U26: 2 | V26: 2 | W26: 2 | X26: 2
A27: ==样本清单!A27 -> M1_P3_08 | B27: ==样本清单!B27 -> M1 | C27: ==样本清单!C27 -> ChatGPT Images 2.0 | D27: ==样本清单!D27 -> P3 | E27: ==样本清单!F27 -> 8 | F27: 2 | G27: 2 | H27: 2 | I27: 1 | J27: 1 | K27: 2 | L27: 2 | M27: 2 | N27: 1 | O27: 2 | P27: 0 | Q27: 0 | R27: 1 | S27: 2 | T27: 1 | U27: 2 | V27: 2 | W27: 2 | X27: 2
A28: ==样本清单!A28 -> M1_P3_09 | B28: ==样本清单!B28 -> M1 | C28: ==样本清单!C28 -> ChatGPT Images 2.0 | D28: ==样本清单!D28 -> P3 | E28: ==样本清单!F28 -> 9 | F28: 2 | G28: 2 | H28: 2 | I28: 2 | J28: 2 | K28: 0 | L28: 2 | M28: 2 | N28: 0 | O28: 2 | P28: 0 | Q28: 0 | R28: 1 | S28: 2 | T28: 2 | U28: 2 | V28: 2 | W28: 2 | X28: 2
A29: ==样本清单!A29 -> M2_P1_01 | B29: ==样本清单!B29 -> M2 | C29: ==样本清单!C29 -> gemini-3.1-flash-image | D29: ==样本清单!D29 -> P1 | E29: ==样本清单!F29 -> 1 | F29: 1 | G29: 1 | H29: 2 | I29: 0 | J29: 2 | K29: 0 | L29: 1 | M29: 0 | N29: 0 | O29: 0 | P29: 0 | Q29: 0 | R29: 0 | S29: 0 | T29: 1 | U29: 1 | V29: 1 | W29: 0 | X29: 0
A30: ==样本清单!A30 -> M2_P1_02 | B30: ==样本清单!B30 -> M2 | C30: ==样本清单!C30 -> gemini-3.1-flash-image | D30: ==样本清单!D30 -> P1 | E30: ==样本清单!F30 -> 2 | F30: 1 | G30: 1 | H30: 2 | I30: 1 | J30: 1 | K30: 0 | L30: 0 | M30: 0 | N30: 0 | O30: 0 | P30: 0 | Q30: 0 | R30: 0 | S30: 0 | T30: 0 | U30: 0 | V30: 1 | W30: 0 | X30: 0
A31: ==样本清单!A31 -> M2_P1_03 | B31: ==样本清单!B31 -> M2 | C31: ==样本清单!C31 -> gemini-3.1-flash-image | D31: ==样本清单!D31 -> P1 | E31: ==样本清单!F31 -> 3 | F31: 1 | G31: 1 | H31: 1 | I31: 1 | J31: 2 | K31: 1 | L31: 2 | M31: 2 | N31: NA | O31: 1 | P31: 0 | Q31: 0 | R31: 0 | S31: 2 | T31: 1 | U31: 1 | V31: 1 | W31: 2 | X31: 1
A32: ==样本清单!A32 -> M2_P1_04 | B32: ==样本清单!B32 -> M2 | C32: ==样本清单!C32 -> gemini-3.1-flash-image | D32: ==样本清单!D32 -> P1 | E32: ==样本清单!F32 -> 4 | F32: 2 | G32: 2 | H32: 2 | I32: 0 | J32: 1 | K32: 0 | L32: 2 | M32: 2 | N32: 2 | O32: 2 | P32: 0 | Q32: 0 | R32: 0 | S32: 2 | T32: 1 | U32: 1 | V32: 1 | W32: 2 | X32: 2
A33: ==样本清单!A33 -> M2_P1_05 | B33: ==样本清单!B33 -> M2 | C33: ==样本清单!C33 -> gemini-3.1-flash-image | D33: ==样本清单!D33 -> P1 | E33: ==样本清单!F33 -> 5 | F33: 1 | G33: 2 | H33: 2 | I33: 0 | J33: 2 | K33: 0 | L33: 2 | M33: 2 | N33: 2 | O33: 2 | P33: 0 | Q33: 0 | R33: 0 | S33: 1 | T33: 1 | U33: 1 | V33: 1 | W33: 1 | X33: 2
A34: ==样本清单!A34 -> M2_P1_06 | B34: ==样本清单!B34 -> M2 | C34: ==样本清单!C34 -> gemini-3.1-flash-image | D34: ==样本清单!D34 -> P1 | E34: ==样本清单!F34 -> 6 | F34: 1 | G34: 1 | H34: 2 | I34: 0 | J34: 2 | K34: 0 | L34: 0 | M34: 1 | N34: NA | O34: 1 | P34: 0 | Q34: 0 | R34: 0 | S34: 1 | T34: 1 | U34: 1 | V34: 1 | W34: 2 | X34: 1
A35: ==样本清单!A35 -> M2_P1_07 | B35: ==样本清单!B35 -> M2 | C35: ==样本清单!C35 -> gemini-3.1-flash-image | D35: ==样本清单!D35 -> P1 | E35: ==样本清单!F35 -> 7 | F35: 1 | G35: 2 | H35: 2 | I35: 0 | J35: 2 | K35: 0 | L35: 0 | M35: 0 | N35: NA | O35: 1 | P35: 0 | Q35: 0 | R35: 0 | S35: 1 | T35: 1 | U35: 1 | V35: 1 | W35: 2 | X35: 2
A36: ==样本清单!A36 -> M2_P1_08 | B36: ==样本清单!B36 -> M2 | C36: ==样本清单!C36 -> gemini-3.1-flash-image | D36: ==样本清单!D36 -> P1 | E36: ==样本清单!F36 -> 8 | F36: 1 | G36: 1 | H36: 2 | I36: 0 | J36: 2 | K36: 0 | L36: 2 | M36: 2 | N36: 2 | O36: 2 | P36: 0 | Q36: 0 | R36: 0 | S36: 1 | T36: 2 | U36: 1 | V36: 1 | W36: 2 | X36: 2
A37: ==样本清单!A37 -> M2_P1_09 | B37: ==样本清单!B37 -> M2 | C37: ==样本清单!C37 -> gemini-3.1-flash-image | D37: ==样本清单!D37 -> P1 | E37: ==样本清单!F37 -> 9 | F37: 2 | G37: 2 | H37: 2 | I37: 1 | J37: 1 | K37: 0 | L37: 2 | M37: 2 | N37: NA | O37: 1 | P37: 0 | Q37: 0 | R37: 0 | S37: 1 | T37: 1 | U37: 1 | V37: 1 | W37: 2 | X37: 2
A38: ==样本清单!A38 -> M2_P2_01 | B38: ==样本清单!B38 -> M2 | C38: ==样本清单!C38 -> gemini-3.1-flash-image | D38: ==样本清单!D38 -> P2 | E38: ==样本清单!F38 -> 1 | F38: 1 | G38: 0 | H38: 2 | I38: 1 | J38: 2 | K38: 0 | L38: 2 | M38: 2 | N38: NA | O38: 2 | P38: 0 | Q38: 0 | R38: 0 | S38: 2 | T38: 1 | U38: 0 | V38: 1 | W38: 2 | X38: 1
A39: ==样本清单!A39 -> M2_P2_02 | B39: ==样本清单!B39 -> M2 | C39: ==样本清单!C39 -> gemini-3.1-flash-image | D39: ==样本清单!D39 -> P2 | E39: ==样本清单!F39 -> 2 | F39: 1 | G39: 0 | H39: 2 | I39: 1 | J39: 0 | K39: 0 | L39: 2 | M39: 2 | N39: 0 | O39: 2 | P39: 0 | Q39: 0 | R39: 0 | S39: 2 | T39: 1 | U39: 0 | V39: 1 | W39: 2 | X39: 1
A40: ==样本清单!A40 -> M2_P2_03 | B40: ==样本清单!B40 -> M2 | C40: ==样本清单!C40 -> gemini-3.1-flash-image | D40: ==样本清单!D40 -> P2 | E40: ==样本清单!F40 -> 3 | F40: 1 | G40: 0 | H40: 2 | I40: 1 | J40: 0 | K40: 0 | L40: 2 | M40: 2 | N40: 0 | O40: 2 | P40: 0 | Q40: 0 | R40: 0 | S40: 2 | T40: 1 | U40: 0 | V40: 1 | W40: 2 | X40: 1
...

Sheet 共识效标Y
A1: ImageID | B1: 模型代码 | C1: 模型名称 | D1: 提示条件 | E1: 重复序号 | F1: Y_A | G1: Y_B | H1: 共识Y | I1: A/B是否一致 | J1: 复核说明
A2: ==样本清单!A2 -> M1_P1_01 | B2: ==样本清单!B2 -> M1 | C2: ==样本清单!C2 -> ChatGPT Images 2.0 | D2: ==样本清单!D2 -> P1 | E2: ==样本清单!F2 -> 1 | F2: {==IF($A2="","",INDEX(编码员A!$F:$F,MATCH($A2,编码员A!$A:$A,0)))} -> 0 | G2: {==IF($A2="","",INDEX(编码员B!$F:$F,MATCH($A2,编码员B!$A:$A,0)))} -> 1 | H2: 0.5 | I2: ==IF(OR(F2="",G2=""),"",IF(F2=G2,1,0)) -> 0 | J2: 分歧：按预注册规则取均值（保留小数）
A3: ==样本清单!A3 -> M1_P1_02 | B3: ==样本清单!B3 -> M1 | C3: ==样本清单!C3 -> ChatGPT Images 2.0 | D3: ==样本清单!D3 -> P1 | E3: ==样本清单!F3 -> 2 | F3: {==IF($A3="","",INDEX(编码员A!$F:$F,MATCH($A3,编码员A!$A:$A,0)))} -> 0 | G3: {==IF($A3="","",INDEX(编码员B!$F:$F,MATCH($A3,编码员B!$A:$A,0)))} -> 0 | H3: 0 | I3: ==IF(OR(F3="",G3=""),"",IF(F3=G3,1,0)) -> 1 | J3: 两人一致，直接采纳
A4: ==样本清单!A4 -> M1_P1_03 | B4: ==样本清单!B4 -> M1 | C4: ==样本清单!C4 -> ChatGPT Images 2.0 | D4: ==样本清单!D4 -> P1 | E4: ==样本清单!F4 -> 3 | F4: {==IF($A4="","",INDEX(编码员A!$F:$F,MATCH($A4,编码员A!$A:$A,0)))} -> 1 | G4: {==IF($A4="","",INDEX(编码员B!$F:$F,MATCH($A4,编码员B!$A:$A,0)))} -> 0 | H4: 0.5 | I4: ==IF(OR(F4="",G4=""),"",IF(F4=G4,1,0)) -> 0 | J4: 分歧：按预注册规则取均值（保留小数）
A5: ==样本清单!A5 -> M1_P1_04 | B5: ==样本清单!B5 -> M1 | C5: ==样本清单!C5 -> ChatGPT Images 2.0 | D5: ==样本清单!D5 -> P1 | E5: ==样本清单!F5 -> 4 | F5: {==IF($A5="","",INDEX(编码员A!$F:$F,MATCH($A5,编码员A!$A:$A,0)))} -> 0 | G5: {==IF($A5="","",INDEX(编码员B!$F:$F,MATCH($A5,编码员B!$A:$A,0)))} -> 0 | H5: 0 | I5: ==IF(OR(F5="",G5=""),"",IF(F5=G5,1,0)) -> 1 | J5: 两人一致，直接采纳
A6: ==样本清单!A6 -> M1_P1_05 | B6: ==样本清单!B6 -> M1 | C6: ==样本清单!C6 -> ChatGPT Images 2.0 | D6: ==样本清单!D6 -> P1 | E6: ==样本清单!F6 -> 5 | F6: {==IF($A6="","",INDEX(编码员A!$F:$F,MATCH($A6,编码员A!$A:$A,0)))} -> 0 | G6: {==IF($A6="","",INDEX(编码员B!$F:$F,MATCH($A6,编码员B!$A:$A,0)))} -> 1 | H6: 0.5 | I6: ==IF(OR(F6="",G6=""),"",IF(F6=G6,1,0)) -> 0 | J6: 分歧：按预注册规则取均值（保留小数）
A7: ==样本清单!A7 -> M1_P1_06 | B7: ==样本清单!B7 -> M1 | C7: ==样本清单!C7 -> ChatGPT Images 2.0 | D7: ==样本清单!D7 -> P1 | E7: ==样本清单!F7 -> 6 | F7: {==IF($A7="","",INDEX(编码员A!$F:$F,MATCH($A7,编码员A!$A:$A,0)))} -> 0 | G7: {==IF($A7="","",INDEX(编码员B!$F:$F,MATCH($A7,编码员B!$A:$A,0)))} -> 1 | H7: 0.5 | I7: ==IF(OR(F7="",G7=""),"",IF(F7=G7,1,0)) -> 0 | J7: 分歧：按预注册规则取均值（保留小数）
A8: ==样本清单!A8 -> M1_P1_07 | B8: ==样本清单!B8 -> M1 | C8: ==样本清单!C8 -> ChatGPT Images 2.0 | D8: ==样本清单!D8 -> P1 | E8: ==样本清单!F8 -> 7 | F8: {==IF($A8="","",INDEX(编码员A!$F:$F,MATCH($A8,编码员A!$A:$A,0)))} -> 1 | G8: {==IF($A8="","",INDEX(编码员B!$F:$F,MATCH($A8,编码员B!$A:$A,0)))} -> 2 | H8: 1.5 | I8: ==IF(OR(F8="",G8=""),"",IF(F8=G8,1,0)) -> 0 | J8: 分歧：按预注册规则取均值（保留小数）
A9: ==样本清单!A9 -> M1_P1_08 | B9: ==样本清单!B9 -> M1 | C9: ==样本清单!C9 -> ChatGPT Images 2.0 | D9: ==样本清单!D9 -> P1 | E9: ==样本清单!F9 -> 8 | F9: {==IF($A9="","",INDEX(编码员A!$F:$F,MATCH($A9,编码员A!$A:$A,0)))} -> 1 | G9: {==IF($A9="","",INDEX(编码员B!$F:$F,MATCH($A9,编码员B!$A:$A,0)))} -> 1 | H9: 1 | I9: ==IF(OR(F9="",G9=""),"",IF(F9=G9,1,0)) -> 1 | J9: 两人一致，直接采纳
A10: ==样本清单!A10 -> M1_P1_09 | B10: ==样本清单!B10 -> M1 | C10: ==样本清单!C10 -> ChatGPT Images 2.0 | D10: ==样本清单!D10 -> P1 | E10: ==样本清单!F10 -> 9 | F10: {==IF($A10="","",INDEX(编码员A!$F:$F,MATCH($A10,编码员A!$A:$A,0)))} -> 0 | G10: {==IF($A10="","",INDEX(编码员B!$F:$F,MATCH($A10,编码员B!$A:$A,0)))} -> 1 | H10: 0.5 | I10: ==IF(OR(F10="",G10=""),"",IF(F10=G10,1,0)) -> 0 | J10: 分歧：按预注册规则取均值（保留小数）
A11: ==样本清单!A11 -> M1_P2_01 | B11: ==样本清单!B11 -> M1 | C11: ==样本清单!C11 -> ChatGPT Images 2.0 | D11: ==样本清单!D11 -> P2 | E11: ==样本清单!F11 -> 1 | F11: {==IF($A11="","",INDEX(编码员A!$F:$F,MATCH($A11,编码员A!$A:$A,0)))} -> 1 | G11: {==IF($A11="","",INDEX(编码员B!$F:$F,MATCH($A11,编码员B!$A:$A,0)))} -> 1 | H11: 1 | I11: ==IF(OR(F11="",G11=""),"",IF(F11=G11,1,0)) -> 1 | J11: 两人一致，直接采纳
A12: ==样本清单!A12 -> M1_P2_02 | B12: ==样本清单!B12 -> M1 | C12: ==样本清单!C12 -> ChatGPT Images 2.0 | D12: ==样本清单!D12 -> P2 | E12: ==样本清单!F12 -> 2 | F12: {==IF($A12="","",INDEX(编码员A!$F:$F,MATCH($A12,编码员A!$A:$A,0)))} -> 1 | G12: {==IF($A12="","",INDEX(编码员B!$F:$F,MATCH($A12,编码员B!$A:$A,0)))} -> 1 | H12: 1 | I12: ==IF(OR(F12="",G12=""),"",IF(F12=G12,1,0)) -> 1 | J12: 两人一致，直接采纳
A13: ==样本清单!A13 -> M1_P2_03 | B13: ==样本清单!B13 -> M1 | C13: ==样本清单!C13 -> ChatGPT Images 2.0 | D13: ==样本清单!D13 -> P2 | E13: ==样本清单!F13 -> 3 | F13: {==IF($A13="","",INDEX(编码员A!$F:$F,MATCH($A13,编码员A!$A:$A,0)))} -> 1 | G13: {==IF($A13="","",INDEX(编码员B!$F:$F,MATCH($A13,编码员B!$A:$A,0)))} -> 1 | H13: 1 | I13: ==IF(OR(F13="",G13=""),"",IF(F13=G13,1,0)) -> 1 | J13: 两人一致，直接采纳
... A163: ==样本清单!A163 -> M6_P3_09 | B163: ==样本清单!B163 -> M6 | C163: ==样本清单!C163 -> HunyuanImage-3.0 | D163: ==样本清单!D163 -> P3 | E163: ==样本清单!F163 -> 9 | F163: {==IF($A163="","",INDEX(编码员A!$F:$F,MATCH($A163,编码员A!$A:$A,0)))} -> 2 | G163: {==IF($A163="","",INDEX(编码员B!$F:$F,MATCH($A163,编码员B!$A:$A,0)))} -> 2 | H163: 2 | I163: ==IF(OR(F163="",G163=""),"",IF(F163=G163,1,0)) -> 1 | J163: 两人一致，直接采纳

Sheet 提示条件汇总
A1: 三类提示条件总体历史失真汇总
A3: 提示条件 | B3: 名称 | C3: Y=0 | D3: Y=0.5 | E3: Y=1 | F3: Y=1.5 | G3: Y=2 | H3: 有效N | I3: 2级失真比例 | J3: 均值Y | K3: 95%CI下限 | L3: 95%CI上限
A4: P1 | B4: 低约束基线 | C4: ==COUNTIFS(共识效标Y!$D$2:$D$163,$A4,共识效标Y!$H$2:$H$163,0) -> 3 | D4: ==COUNTIFS(共识效标Y!$D$2:$D$163,$A4,共识效标Y!$H$2:$H$163,0.5) -> 9 | E4: ==COUNTIFS(共识效标Y!$D$2:$D$163,$A4,共识效标Y!$H$2:$H$163,1) -> 10 | F4: ==COUNTIFS(共识效标Y!$D$2:$D$163,$A4,共识效标Y!$H$2:$H$163,1.5) -> 12 | G4: ==COUNTIFS(共识效标Y!$D$2:$D$163,$A4,共识效标Y!$H$2:$H$163,2) -> 20 | H4: ==SUM(C4:G4) -> 54 | I4: ==IF(H4=0,"",G4/H4) -> 0.37037037 | J4: ==IF(H4=0,"",(0.5*D4+E4+1.5*F4+2*G4)/H4) -> 1.3425926 | K4: 1.1711 | L4: 1.5141
A5: P2 | B5: 考据约束 | C5: ==COUNTIFS(共识效标Y!$D$2:$D$163,$A5,共识效标Y!$H$2:$H$163,0) -> 0 | D5: ==COUNTIFS(共识效标Y!$D$2:$D$163,$A5,共识效标Y!$H$2:$H$163,0.5) -> 0 | E5: ==COUNTIFS(共识效标Y!$D$2:$D$163,$A5,共识效标Y!$H$2:$H$163,1) -> 21 | F5: ==COUNTIFS(共识效标Y!$D$2:$D$163,$A5,共识效标Y!$H$2:$H$163,1.5) -> 17 | G5: ==COUNTIFS(共识效标Y!$D$2:$D$163,$A5,共识效标Y!$H$2:$H$163,2) -> 16 | H5: ==SUM(C5:G5) -> 54 | I5: ==IF(H5=0,"",G5/H5) -> 0.2962963 | J5: ==IF(H5=0,"",(0.5*D5+E5+1.5*F5+2*G5)/H5) -> 1.4537037 | K5: 1.343 | L5: 1.5644
A6: P3 | B6: 负向关系框架 | C6: ==COUNTIFS(共识效标Y!$D$2:$D$163,$A6,共识效标Y!$H$2:$H$163,0) -> 0 | D6: ==COUNTIFS(共识效标Y!$D$2:$D$163,$A6,共识效标Y!$H$2:$H$163,0.5) -> 1 | E6: ==COUNTIFS(共识效标Y!$D$2:$D$163,$A6,共识效标Y!$H$2:$H$163,1) -> 14 | F6: ==COUNTIFS(共识效标Y!$D$2:$D$163,$A6,共识效标Y!$H$2:$H$163,1.5) -> 13 | G6: ==COUNTIFS(共识效标Y!$D$2:$D$163,$A6,共识效标Y!$H$2:$H$163,2) -> 26 | H6: ==SUM(C6:G6) -> 54 | I6: ==IF(H6=0,"",G6/H6) -> 0.48148148 | J6: ==IF(H6=0,"",(0.5*D6+E6+1.5*F6+2*G6)/H6) -> 1.5925926 | K6: 1.4737 | L6: 1.7115
A9: 维度级结果（真实统计后填写） | B9: P1 | C9: P2 | D9: P3 | E9: 效应口径 | F9: P3 | G9: 效应口径 | H9: 说明
A10: D1 建筑与场景时代一致性 | B10: 1.528 | C10: 1.593 | D10: 1.852 | E10: 维度分均值（0—2） | F10: D1=f2；D5=f18为稳定指标口径；D2—D4按维度内全部原子指标均值
A11: D2 服饰、器物与武备 | B11: 1.253 | C11: 1.527 | D11: 1.586 | E11: 维度分均值（0—2）
A12: D3 族群身份与社会关系 | B12: 0.364 | C12: 0.377 | D12: 0.593 | E12: 维度分均值（0—2）
A13: D4 空间构图与历史视觉语法 | B13: 1.201 | C13: 1.442 | D13: 1.544 | E13: 维度分均值（0—2）
A14: D5 生成完整性与提示词遵循 | B14: 1.481 | C14: 1.528 | D14: 1.667 | E14: 维度分均值（0—2）
A15: 备注 | F15: 图3b使用本区数据。
A16: 维度分口径：D1—D5 均按第一轮编码A/B均值（保留小数、每图计一次）：D1=f2、D5=f18 单指标均值；D2—D4 为维度内全部原子指标均值。共识Y与维度分均保留精确小数（0.5/1.5 为独立取值，不四舍五入）。

Sheet 稳定性_留一
A1: 指标 | B1: 含义 | C1: Bootstrap选择频率πj | D1: 剔除M1 | E1: 剔除M2 | F1: 剔除M3 | G1: 剔除M4 | H1: 剔除M5 | I1: 剔除M6 | J1: 入选次数 | K1: π达标 | L1: 最终稳定
A2: f1 | B2: 屋顶、佛塔与比例 | C2: 0.273 | D2: 0 | E2: 0 | F2: 0 | G2: 1 | H2: 0 | I2: 1 | J2: ==SUM(D2:I2) -> 2 | K2: ==IF(C2="","",IF(C2>=0.6,"是","否")) -> 否 | L2: ==IF(OR(C2="",J2=""),"",IF(AND(C2>=0.6,J2>=5),"是","否")) -> 否
A3: f2 | B3: 城墙与门楼 | C3: 0.732 | D3: 0 | E3: 1 | F3: 1 | G3: 1 | H3: 1 | I3: 1 | J3: ==SUM(D3:I3) -> 5 | K3: ==IF(C3="","",IF(C3>=0.6,"是","否")) -> 是 | L3: ==IF(OR(C3="",J3=""),"",IF(AND(C3>=0.6,J3>=5),"是","否")) -> 是
A4: f3 | B4: 衣袍领型 | C4: 0.308 | D4: 0 | E4: 0 | F4: 0 | G4: 0 | H4: 1 | I4: 0 | J4: ==SUM(D4:I4) -> 1 | K4: ==IF(C4="","",IF(C4>=0.6,"是","否")) -> 否 | L4: ==IF(OR(C4="",J4=""),"",IF(AND(C4>=0.6,J4>=5),"是","否")) -> 否
A5: f4 | B5: 腰带配件 | C5: 0.112 | D5: 0 | E5: 0 | F5: 0 | G5: 0 | H5: 0 | I5: 0 | J5: ==SUM(D5:I5) -> 0 | K5: ==IF(C5="","",IF(C5>=0.6,"是","否")) -> 否 | L5: ==IF(OR(C5="",J5=""),"",IF(AND(C5>=0.6,J5>=5),"是","否")) -> 否
A6: f5 | B6: 头饰须发 | C6: 0.178 | D6: 1 | E6: 0 | F6: 0 | G6: 0 | H6: 0 | I6: 0 | J6: ==SUM(D6:I6) -> 1 | K6: ==IF(C6="","",IF(C6>=0.6,"是","否")) -> 否 | L6: ==IF(OR(C6="",J6=""),"",IF(AND(C6>=0.6,J6>=5),"是","否")) -> 否
A7: f6 | B7: 书籍家具 | C7: 0.208 | D7: 0 | E7: 1 | F7: 0 | G7: 0 | H7: 0 | I7: 0 | J7: ==SUM(D7:I7) -> 1 | K7: ==IF(C7="","",IF(C7>=0.6,"是","否")) -> 否 | L7: ==IF(OR(C7="",J7=""),"",IF(AND(C7>=0.6,J7>=5),"是","否")) -> 否
A8: f7 | B8: 饮食贸易器皿 | C8: 0.01 | D8: 0 | E8: 0 | F8: 0 | G8: 0 | H8: 0 | I8: 0 | J8: ==SUM(D8:I8) -> 0 | K8: ==IF(C8="","",IF(C8>=0.6,"是","否")) -> 否 | L8: ==IF(OR(C8="",J8=""),"",IF(AND(C8>=0.6,J8>=5),"是","否")) -> 否
A9: f8 | B9: 兵器铠甲 | C9: 0.141 | D9: 0 | E9: 0 | F9: 0 | G9: 0 | H9: 0 | I9: 0 | J9: ==SUM(D9:I9) -> 0 | K9: ==IF(C9="","",IF(C9>=0.6,"是","否")) -> 否 | L9: ==IF(OR(C9="",J9=""),"",IF(AND(C9>=0.6,J9>=5),"是","否")) -> 否
A10: f9 | B10: 马匹马具车辆 | C10: 0.076 | D10: 0 | E10: 0 | F10: 0 | G10: 0 | H10: 0 | I10: 0 | J10: ==SUM(D10:I10) -> 0 | K10: ==IF(C10="","",IF(C10>=0.6,"是","否")) -> 否 | L10: ==IF(OR(C10="",J10=""),"",IF(AND(C10>=0.6,J10>=5),"是","否")) -> 否
A11: f10 | B11: 具体身份可辨识度 | C11: 0.092 | D11: 0 | E11: 0 | F11: 0 | G11: 0 | H11: 0 | I11: 0 | J11: ==SUM(D11:I11) -> 0 | K11: ==IF(C11="","",IF(C11>=0.6,"是","否")) -> 否 | L11: ==IF(OR(C11="",J11=""),"",IF(AND(C11>=0.6,J11>=5),"是","否")) -> 否
A12: f11 | B12: 族群标签化 | C12: 0.203 | D12: 0 | E12: 0 | F12: 1 | G12: 0 | H12: 0 | I12: 0 | J12: ==SUM(D12:I12) -> 1 | K12: ==IF(C12="","",IF(C12>=0.6,"是","否")) -> 否 | L12: ==IF(OR(C12="",J12=""),"",IF(AND(C12>=0.6,J12>=5),"是","否")) -> 否
A13: f12 | B13: 社会身份与互动 | C13: 0.251 | D13: 0 | E13: 1 | F13: 0 | G13: 1 | H13: 0 | I13: 0 | J13: ==SUM(D13:I13) -> 2 | K13: ==IF(C13="","",IF(C13>=0.6,"是","否")) -> 否 | L13: ==IF(OR(C13="",J13=""),"",IF(AND(C13>=0.6,J13>=5),"是","否")) -> 否
... A19: f18 | B19: 提示词遵循度 | C19: 0.995 | D19: 1 | E19: 1 | F19: 1 | G19: 1 | H19: 1 | I19: 1 | J19: ==SUM(D19:I19) -> 6 | K19: ==IF(C19="","",IF(C19>=0.6,"是","否")) -> 是 | L19: ==IF(OR(C19="",J19=""),"",IF(AND(C19>=0.6,J19>=5),"是","否")) -> 是
A21: 方法：特征=编码员A/B 原子指标均值（NA→0，保留小数）；目标=共识效标Y（保留小数）；回归CART（树深≤3，叶节点≥15，random_state=0）；10000 次模型分层 Bootstrap（种子 20260824）；留一模型每次剔除27张保留135张。全数据最终树：树深3、终端节点6。稳定判据：π≥0.60 且六次留一至少5次入选。

Sheet 维度_Kappa
A1: 最终维度与编码者间信度填写区
A3: 总体效标Y信度 | B3: 值 | C3: CI下限 | D3: CI上限
A4: 线性加权Kappa | B4: 0.46 | C4: 0.346 | D4: 0.568
A5: 说明 | B5: 两名专家讨论前独立评分；共识Y仅用于维度筛选。
A6: 提示 | B6: Kappa及CI由R/Python统计后粘贴黄色单元格。
A9: 最终维度 | B9: 稳定原子指标 | C9: π范围 | D9: 留一模型入选次数 | E9: 有效N | F9: 线性加权κg | G9: CI下限 | H9: CI上限 | I9: 备注
A10: D1 建筑与场景时代一致性 | B10: f2 | C10: 0.273—0.732 | D10: 2—5 | E10: 162 | F10: 0.579 | G10: 0.476 | H10: 0.676 | I10: 稳定指标：f2
A11: D2 服饰、器物与武备 | B11: 无达标指标 | C11: 0.010—0.308 | D11: 0—1 | E11: 162 | F11: 0.649 | G11: 0.61 | H11: 0.686 | I11: κg按维度内全部原子指标计算
A12: D3 族群身份与社会关系 | B12: 无达标指标 | C12: 0.092—0.251 | D12: 0—2 | E12: 162 | F12: 0.788 | G12: 0.742 | H12: 0.831 | I12: κg按维度内全部原子指标计算
A13: D4 空间构图与历史视觉语法 | B13: 无达标指标 | C13: 0.081—0.539 | D13: 0—4 | E13: 162 | F13: 0.407 | G13: 0.35 | H13: 0.462 | I13: κg按维度内全部原子指标计算
A14: D5 生成完整性与提示词遵循 | B14: f18 | C14: 0.051—0.995 | D14: 0—6 | E14: 162 | F14: 0.535 | G14: 0.419 | H14: 0.64 | I14: 稳定指标：f18
A15: 微观合并综合（2828对） | B15: — | C15: — | D15: — | E15: 162 | F15: 0.671 | G15: 0.65 | H15: 0.692 | I15: κpool为全部2828个图像×指标对池化后的标准线性加权Kappa，仅为总体一致性描述，不能替代分维度κg。
A17: 口径：κg 按维度内全部原子指标的图像×指标对合并计算（D1=f2、D5=f18 单指标，等价）；95%CI 为 2000 次单元内分层 Bootstrap（种子 20260824）百分位区间；Krippendorff α 采用区间度量。全部仅依赖编码员A/B 原始评分。

Sheet 正文填数索引
A1: 编号 | B1: 正文/图表字段 | C1: 应填内容 | D1: 来源位置 | E1: 当前值/公式 | F1: 状态 | G1: 备注
A2: 1 | B2: 实际失败次数 | C2: 失败/拒绝且按预注册规则补足的次数 | D2: 样本清单!I2:I163 | E2: {==IF(COUNTIF(样本清单!I2:I163,"失败/拒绝")=0,"",COUNTIF(样本清单!I2:I163,"失败/拒绝"))} | F2: 自动 | G2: 未填写生成状态时保持空白。
A3: 2 | B3: 总体专家Y Kappa | C3: 线性加权Kappa | D3: 维度_Kappa!B4 | E3: ==IF(维度_Kappa!B4="","",维度_Kappa!B4) -> 0.46 | F3: 链接
A4: 3 | B4: 总体专家Y 95% CI下限 | C4: CI下限 | D4: 维度_Kappa!C4 | E4: ==IF(维度_Kappa!C4="","",维度_Kappa!C4) -> 0.346 | F4: 链接
A5: 4 | B5: 总体专家Y 95% CI上限 | C5: CI上限 | D5: 维度_Kappa!D4 | E5: ==IF(维度_Kappa!D4="","",维度_Kappa!D4) -> 0.568 | F5: 链接
A6: 5 | B6: 稳定原子指标数量 | C6: 满足π≥0.60且6次留一≥5次的指标数 | D6: 稳定性_留一!L2:L19 | E6: {==IF(COUNTIF(稳定性_留一!L2:L19,"是")=0,"",COUNTIF(稳定性_留一!L2:L19,"是"))} -> 2 | F6: 自动
A7: 6 | B7: 选择频率较高指标及πj | C7: 正文列出若干最高指标 | D7: 稳定性_留一!A:C | E7: f18（π=0.995）；f2（π=0.732） | F7: 手工 | G7: 建议按πj降序选3—5项
A8: 7 | B8: 最终维度数量 | C8: 稳定指标归并后的维度数 | D8: 维度_Kappa!A10:A14 | E8: 2 | F8: 手工 | G8: 真实稳定性分析后锁定
A9: 8 | B9: 最终树深 | C9: CART输出 | D9: 统计程序 | E9: 3 | F9: 手工
A10: 9 | B10: 终端节点数 | C10: CART输出 | D10: 统计程序 | E10: 6 | F10: 手工
A11: 10 | B11: P1 2级总体失真比例 | C11: Y=2/N | D11: 提示条件汇总!I4 | E11: ==IF(提示条件汇总!I4="","",提示条件汇总!I4) -> 0.37037037 | F11: 自动
A12: 11 | B12: P2 2级总体失真比例 | C12: Y=2/N | D12: 提示条件汇总!I5 | E12: ==IF(提示条件汇总!I5="","",提示条件汇总!I5) -> 0.2962963 | F12: 自动
A13: 12 | B13: P3 2级总体失真比例 | C13: Y=2/N | D13: 提示条件汇总!I6 | E13: ==IF(提示条件汇总!I6="","",提示条件汇总!I6) -> 0.48148148 | F13: 自动
A14: 13 | B14: 建筑比例/器物年代等πj | C14: 正文机制段落使用 | D14: 稳定性_留一!C:C | E14: f2城墙与门楼 π=0.732 | F14: 手工 | G14: 按真实入选结果决定写哪些
A15: 14 | B15: 族群标签化πj | C15: f11选择频率 | D15: 稳定性_留一!C12 | E15: ==IF(稳定性_留一!C12="","",稳定性_留一!C12) -> 0.203 | F15: 链接 | G15: f11位于第12行
A16: 15 | B16: D4 Kappa | C16: 空间构图与历史视觉语法κ | D16: 维度_Kappa!F13 | E16: ==IF(维度_Kappa!F13="","",维度_Kappa!F13) -> 0.407 | F16: 链接
A17: 16 | B17: D4 95% CI下限 | C17: D4 CI下限 | D17: 维度_Kappa!G13 | E17: ==IF(维度_Kappa!G13="","",维度_Kappa!G13) -> 0.35 | F17: 链接
A18: 17 | B18: D4 95% CI上限 | C18: D4 CI上限 | D18: 维度_Kappa!H13 | E18: ==IF(维度_Kappa!H13="","",维度_Kappa!H13) -> 0.462 | F18: 链接
A19: 18 | B19: P1→P2 2级失真变化 | C19: P2比例-P1比例 | D19: 提示条件汇总!I4:I5 | E19: ==IF(OR(提示条件汇总!I4="",提示条件汇总!I5=""),"",提示条件汇总!I5-提示条件汇总!I4) -> -0.074074074 | F19: 自动 | G19: 负值=下降
A20: 19 | B20: P2→P3 2级失真变化 | C20: P3比例-P2比例 | D20: 提示条件汇总!I5:I6 | E20: ==IF(OR(提示条件汇总!I5="",提示条件汇总!I6=""),"",提示条件汇总!I6-提示条件汇总!I5) -> 0.18518519 | F20: 自动 | G20: 正值=上升
A21: 20 | B21: κpool（微观合并） | C21: 全部图像×指标对池化后的总体一致性（标准线性加权Kappa） | D21: 维度_Kappa!F15 | E21: ==IF(维度_Kappa!F15="","",维度_Kappa!F15) -> 0.671 | F21: 链接
A22: 21 | B22: κpool CI下限 | C22: 95% CI下限 | D22: 维度_Kappa!G15 | E22: ==IF(维度_Kappa!G15="","",维度_Kappa!G15) -> 0.65 | F22: 链接
A23: 22 | B23: κpool CI上限 | C23: 95% CI上限 | D23: 维度_Kappa!H15 | E23: ==IF(维度_Kappa!H15="","",维度_Kappa!H15) -> 0.692 | F23: 链接
A24: 23 | B24: 研究伦理自查编号 | C24: 伦理审批/自查编号 | D24: 研究记录 | E24: （ ） | F24: 手工 | G24: 如期刊要求提供

Sheet 提示词全文
A1: 条件 | B1: 名称 | C1: 完整英文提示词（实际投喂文本） | D1: 每模型n | E1: 全条件N
A2: P1 | B2: 低约束基线 | C2: Tang dynasty, a Han Chinese scholar and a Sogdian merchant meeting at a Silk Road frontier post, both figures shown in the same scene, with surrounding architecture, a caravan, horses, and everyday objects visible, Tang-dynasty mural painting style. | D2: 9 | E2: 54
A3: P2 | B3: 考据约束 | C3: Tang dynasty, a Han Chinese scholar and a Sogdian merchant meeting at a Silk Road frontier post, both figures shown in the same scene, with surrounding architecture, a caravan, horses, and everyday objects visible. Use historically grounded Tang-period clothing, headwear, belts, low furniture, scroll-format books, vessels, architecture, horse tack, and caravan equipment. Convey the Sogdian merchant’s identity through period-appropriate dress, occupation, and trade context rather than exaggerated facial features or skin color. Tang-dynasty mural painting style. | D3: 9 | E3: 54
A4: P3 | B4: 负向关系框架 | C4: Tang dynasty, a Han Chinese scholar and a Sogdian merchant at a Silk Road frontier post, with surrounding architecture, a caravan, horses, guards, and everyday objects visible. A tense confrontation has arisen over caravan passage and trade inspection; show guarded gestures, defensive postures, and social tension, without depicting either group as inherently savage or culturally inferior. Use historically grounded Tang-period clothing, headwear, belts, vessels, architecture, weapons, armor, horse tack, and caravan equipment. Convey historical identities through period-appropriate material culture and social context rather than exaggerated facial features or skin color. Tang-dynasty mural painting style. | D4: 9 | E4: 54
